<?xml version="1.0"?>
<robot name="two_wheel_robot">
  <!-- Base Link -->
  <link name="base_link">
    <visual>
      <geometry>
        <box size="0.9 0.6 0.15"/>
      </geometry>
      <material name="blue">
        <color rgba="0 0 1 1"/>
      </material>
    </visual>
    <collision>
      <geometry>
        <box size="0.9 0.6 0.15"/>
      </geometry>
    </collision>
    <inertial>
      <mass value="5.0"/>
      <origin xyz="0 0 0" rpy="0 0 0"/>
      <inertia ixx="0.1" ixy="0" ixz="0" iyy="0.1" iyz="0" izz="0.1"/>
    </inertial>
  </link>

  <!-- Right Wheel -->
  <link name="right_wheel">
    <visual>
      <geometry>
        <cylinder radius="0.15" length="0.12"/>
      </geometry>
      <material name="black">
        <color rgba="0 0 0 1"/>
      </material>
    </visual>
    <collision>
      <geometry>
        <cylinder radius="0.15" length="0.12"/>
      </geometry>
    </collision>
    <inertial>
      <mass value="1.0"/>
      <origin xyz="0 0 0" rpy="0 0 0"/>
      <inertia ixx="0.01" ixy="0" ixz="0" iyy="0.01" iyz="0" izz="0.01"/>
    </inertial>
  </link>

  <!-- Left Wheel -->
  <link name="left_wheel">
    <visual>
      <geometry>
        <cylinder radius="0.15" length="0.12"/>
      </geometry>
      <material name="black"/>
    </visual>
    <collision>
      <geometry>
        <cylinder radius="0.15" length="0.12"/>
      </geometry>
    </collision>
    <inertial>
      <mass value="1.0"/>
      <origin xyz="0 0 0" rpy="0 0 0"/>
      <inertia ixx="0.01" ixy="0" ixz="0" iyy="0.01" iyz="0" izz="0.01"/>
    </inertial>
  </link>

  <!-- Caster Wheel -->
  <link name="caster">
    <visual>
      <geometry>
        <sphere radius="0.06"/>
      </geometry>
      <material name="black"/>
    </visual>
    <collision>
      <geometry>
        <sphere radius="0.06"/>
      </geometry>
    </collision>
    <inertial>
      <mass value="0.5"/>
      <origin xyz="0 0 0" rpy="0 0 0"/>
      <inertia ixx="0.001" ixy="0" ixz="0" iyy="0.001" iyz="0" izz="0.001"/>
    </inertial>
  </link>

  <!-- IMU Link -->
  <link name="imu_link">
    <visual>
      <geometry>
        <box size="0.06 0.06 0.06"/>
      </geometry>
      <material name="red">
        <color rgba="1 0 0 1"/>
      </material>
    </visual>
    <collision>
      <geometry>
        <box size="0.06 0.06 0.06"/>
      </geometry>
    </collision>
    <inertial>
      <mass value="0.1"/>
      <origin xyz="0 0 0" rpy="0 0 0"/>
      <inertia ixx="0.001" ixy="0" ixz="0" iyy="0.001" iyz="0" izz="0.001"/>
    </inertial>
  </link>

  <!-- GPS Link -->
  <link name="gps_link">
    <visual>
      <geometry>
        <cylinder radius="0.06" length="0.06"/>
      </geometry>
      <material name="green">
        <color rgba="0 1 0 1"/>
      </material>
    </visual>
    <collision>
      <geometry>
        <cylinder radius="0.06" length="0.06"/>
      </geometry>
    </collision>
    <inertial>
      <mass value="0.1"/>
      <origin xyz="0 0 0" rpy="0 0 0"/>
      <inertia ixx="0.001" ixy="0" ixz="0" iyy="0.001" iyz="0" izz="0.001"/>
    </inertial>
  </link>

  <!-- Lidar Link -->
  <link name="lidar_link">
    <visual>
      <geometry>
        <cylinder radius="0.09" length="0.06"/>
      </geometry>
      <material name="black"/>
    </visual>
    <collision>
      <geometry>
        <cylinder radius="0.09" length="0.06"/>
      </geometry>
    </collision>
    <inertial>
      <mass value="0.2"/>
      <origin xyz="0 0 0" rpy="0 0 0"/>
      <inertia ixx="0.001" ixy="0" ixz="0" iyy="0.001" iyz="0" izz="0.001"/>
    </inertial>
  </link>
  
  <!-- H-Boom Link -->
<link name="h_boom">
  <visual>
    <geometry>
      <box size="0.02 0.02 0.5"/> <!-- Vertical boom -->
    </geometry>
    <material name="silver">
      <color rgba="0.75 0.75 0.75 1"/>
    </material>
  </visual>
  <collision>
    <geometry>
      <box size="0.02 0.02 0.5"/>
    </geometry>
  </collision>
  <inertial>
    <mass value="1.0"/>
    <origin xyz="0 0 0.25" rpy="0 0 0"/>
    <inertia ixx="0.01" ixy="0" ixz="0" iyy="0.01" iyz="0" izz="0.01"/>
  </inertial>
</link>

  <!-- Depth Camera Link -->
  <link name="depth_camera_link">
    <visual>
      <geometry>
        <box size="0.03 0.03 0.03"/>
      </geometry>
      <material name="gray">
        <color rgba="0.5 0.5 0.5 1"/>
      </material>
    </visual>
  </link>
  <link name="depth_camera_link_optical"></link>


  <!-- JOINTS -->
  <joint name="right_wheel_joint" type="continuous">
    <parent link="base_link"/>
    <child link="right_wheel"/>
    <origin xyz="0 -0.36 0" rpy="-1.5708 0 0"/>
    <axis xyz="0 0 1"/>
    <dynamics damping="0.1" friction="0.1"/>
  </joint>

  <joint name="left_wheel_joint" type="continuous">
    <parent link="base_link"/>
    <child link="left_wheel"/>
    <origin xyz="0 0.36 0" rpy="-1.5708 0 0"/>
    <axis xyz="0 0 1"/>
    <dynamics damping="0.1" friction="0.1"/>
  </joint>

  <joint name="caster_joint" type="fixed">
    <parent link="base_link"/>
    <child link="caster"/>
    <origin xyz="0.3 0 -0.09"/>
  </joint>

  <joint name="imu_joint" type="fixed">
    <parent link="base_link"/>
    <child link="imu_link"/>
    <origin xyz="0 0 0.075"/>
  </joint>

  <joint name="gps_joint" type="fixed">
    <parent link="base_link"/>
    <child link="gps_link"/>
    <origin xyz="-0.3 0 0.075"/>
  </joint>

  <joint name="lidar_joint" type="fixed">
    <parent link="base_link"/>
    <child link="lidar_link"/>
    <origin xyz="0.3 0 0.105"/>
  </joint>
  
  <joint name="h_boom_joint" type="fixed">
    <parent link="base_link"/>
    <child link="h_boom"/>
    <origin xyz="0 0 0.15" rpy="0 0 0"/> <!-- Adjust height as needed -->
  </joint>
  
  <joint name="depth_camera_joint" type="fixed">
    <parent link="h_boom"/>
    <child link="depth_camera_link"/>
    <origin xyz="0 0 0.25" rpy="0 0 0"/>
  </joint>

  <joint name="depth_camera_joint_optical" type="fixed">
    <origin xyz="0 0 0" rpy="-1.5708 0 -1.5708"/>
    <parent link="depth_camera_link"/>
    <child link="depth_camera_link_optical"/>
  </joint>



  <!-- Gazebo Material Colors -->
  <gazebo reference="base_link">
    <material>Gazebo/Blue</material>
    <mu1>0.2</mu1>
    <mu2>0.2</mu2>
  </gazebo>

  <gazebo reference="left_wheel">
    <material>Gazebo/Black</material>
    <mu1>1.0</mu1>
    <mu2>1.0</mu2>
    <kp>1000000.0</kp>
    <kd>100.0</kd>
    <minDepth>0.001</minDepth>
  </gazebo>

  <gazebo reference="right_wheel">
    <material>Gazebo/Black</material>
    <mu1>1.0</mu1>
    <mu2>1.0</mu2>
    <kp>1000000.0</kp>
    <kd>100.0</kd>
    <minDepth>0.001</minDepth>
  </gazebo>

  <gazebo reference="caster">
    <material>Gazebo/Black</material>
    <mu1>0.1</mu1>
    <mu2>0.1</mu2>
    <kp>1000000.0</kp>
    <kd>100.0</kd>
    <minDepth>0.001</minDepth>
  </gazebo>

  <!-- Gazebo Plugins -->

  <!-- Differential Drive Plugin -->
  <gazebo>
    <plugin name="differential_drive_controller" filename="libgazebo_ros_diff_drive.so">
      <left_joint>left_wheel_joint</left_joint>
      <right_joint>right_wheel_joint</right_joint>
      <wheel_separation>0.72</wheel_separation>
      <wheel_diameter>0.3</wheel_diameter>
      <max_wheel_torque>20</max_wheel_torque>
      <max_wheel_acceleration>0.5</max_wheel_acceleration>
      <publish_odom>true</publish_odom>
      <publish_wheel_tf>true</publish_wheel_tf>
      <publish_wheel_joint_state>true</publish_wheel_joint_state>
      <odometry_topic>odom</odometry_topic>
      <robot_base_frame>base_link</robot_base_frame>
      <odometry_frame>odom</odometry_frame>
      <commandTopic>cmd_vel</commandTopic>
      <update_rate>50</update_rate>
      <linear>
        <x>
          <has_velocity_limits>true</has_velocity_limits>
          <max_velocity>0.5</max_velocity>
        </x>
      </linear>
      <angular>
        <z>
          <has_velocity_limits>true</has_velocity_limits>
          <max_velocity>1.0</max_velocity>
        </z>
      </angular>
    </plugin>
  </gazebo>

  <!-- IMU Plugin -->
  <gazebo reference="imu_link">
    <gravity>true</gravity>
    <sensor name="imu_sensor" type="imu">
      <always_on>true</always_on>
      <update_rate>100</update_rate>
      <visualize>true</visualize>
      <plugin name="imu_plugin" filename="libgazebo_ros_imu_sensor.so">
        <ros>
          <namespace>/</namespace>
          <remapping>~/out:=imu</remapping>
        </ros>
        <initial_orientation_as_reference>false</initial_orientation_as_reference>
      </plugin>
    </sensor>
  </gazebo>

  <!-- GPS Plugin -->
  <gazebo reference="gps_link">
    <sensor name="gps" type="gps">
      <always_on>true</always_on>
      <update_rate>10</update_rate>
      <plugin name="gps_plugin" filename="libgazebo_ros_gps_sensor.so">
        <ros>
          <namespace>/</namespace>
          <remapping>~/out:=gps</remapping>
        </ros>
      </plugin>
    </sensor>
  </gazebo>

  <!-- Lidar Plugin -->
  <gazebo reference="lidar_link">
    <sensor name="lidar" type="ray">
      <pose>0 0 0 0 0 0</pose>
      <visualize>false</visualize>
      <update_rate>10</update_rate>
      <ray>
        <scan>
          <horizontal>
            <samples>360</samples>
            <resolution>1</resolution>
            <min_angle>-3.14159</min_angle>
            <max_angle>3.14159</max_angle>
          </horizontal>
        </scan>
        <range>
          <min>0.1</min>
          <max>30.0</max>
          <resolution>0.01</resolution>
        </range>
      </ray>
      <plugin name="laser_controller" filename="libgazebo_ros_ray_sensor.so">
        <ros>
          <namespace>/</namespace>
          <remapping>~/out:=scan</remapping>
        </ros>
        <output_type>sensor_msgs/LaserScan</output_type>
        <frame_name>lidar_link</frame_name>
      </plugin>
    </sensor>
  </gazebo>

  <!-- Depth camera plugin -->
  <gazebo reference="depth_camera_link">
    <sensor name="depth_camera" type="depth">
      <pose>0 0 0 0 0 0</pose>
      <visualize>true</visualize>
      <update_rate>30</update_rate>
      <camera>
        <horizontal_fov>1.089</horizontal_fov>
        <image>
          <format>R8G8B8</format>
          <width>640</width>
          <height>480</height>
        </image>
        <clip>
          <near>0.01</near>
          <far>10.0</far>
        </clip>
      </camera>
      <plugin name="depth_camera_controller" filename="libgazebo_ros_camera.so">
      
        <!--<ros>
          <namespace>/</namespace>
          <remapping>~/image:=/depth_camera/image_raw</remapping>
          <remapping>~/camera_info:=/depth_camera/camera_info</remapping>
        </ros> -->
        
        <frame_name>depth_camera_link_optical</frame_name>
      </plugin>
    </sensor>
  </gazebo>

</robot>
